<sdf version="1.8">
	<model name="jet_ski">
	  <pose>0 0 1 0 0 0</pose>
	  <self_collide>false</self_collide>
	  <link name="base_link">
	    <inertial>
		    <mass>1590.0</mass>
		    <inertia>
		      <ixx>908.6</ixx>
		      <ixy>0</ixy>
		      <ixz>0</ixz>
		      <iyy>908.6</iyy>
		      <iyz>0</iyz>
		      <izz>161.0</izz>
		    </inertia>
		  </inertial>
	    <visual name="jet_ski/BaseVisual">
	      <geometry>
		<mesh>
		  <uri>model://jet_ski/meshes/jet_ski.stl</uri>
		  <scale>1 1 1</scale>
		</mesh>
	      </geometry>
	    </visual>
	    <collision name="jet_ski/BaseCollision">
	      <geometry>
		    <cylinder>
		      <radius>0.45</radius>
		      <length>2.5</length>
		    </cylinder>
	      </geometry>
	      <material>
    		<ambient>0.2 0.2 0.2 1</ambient>
    		<diffuse>0.7 0.7 0.7 1</diffuse>
    		<specular>0.5 0.5 0 1</specular>
    		<emissive>0.5 0.5 0 0</emissive>
  	      </material>
	    </collision>
	    <sensor name="imu_sensor" type="imu">
		<always_on>1</always_on>
		<update_rate>250</update_rate>
		<imu>
			<angular_velocity>
				<x>
				<noise type="gaussian">
					<mean>0</mean>
					<stddev>0.0003394</stddev>
					<dynamic_bias_stddev>3.8785e-05</dynamic_bias_stddev>
					<dynamic_bias_correlation_time>1000</dynamic_bias_correlation_time>
				</noise>
				</x>
				<y>
				<noise type="gaussian">
					<mean>0</mean>
					<stddev>0.0003394</stddev>
					<dynamic_bias_stddev>3.8785e-05</dynamic_bias_stddev>
					<dynamic_bias_correlation_time>1000</dynamic_bias_correlation_time>
				</noise>
				</y>
				<z>
				<noise type="gaussian">
					<mean>0</mean>
					<stddev>0.0003394</stddev>
					<dynamic_bias_stddev>3.8785e-05</dynamic_bias_stddev>
					<dynamic_bias_correlation_time>1000</dynamic_bias_correlation_time>
				</noise>
				</z>
			</angular_velocity>
			<linear_acceleration>
				<x>
				<noise type="gaussian">
					<mean>0</mean>
					<stddev>0.004</stddev>
					<dynamic_bias_stddev>0.006</dynamic_bias_stddev>
					<dynamic_bias_correlation_time>300</dynamic_bias_correlation_time>
				</noise>
				</x>
				<y>
				<noise type="gaussian">
					<mean>0</mean>
					<stddev>0.004</stddev>
					<dynamic_bias_stddev>0.006</dynamic_bias_stddev>
					<dynamic_bias_correlation_time>300</dynamic_bias_correlation_time>
				</noise>
				</y>
				<z>
				<noise type="gaussian">
					<mean>0</mean>
					<stddev>0.004</stddev>
					<dynamic_bias_stddev>0.006</dynamic_bias_stddev>
					<dynamic_bias_correlation_time>300</dynamic_bias_correlation_time>
				</noise>
				</z>
			</linear_acceleration>
		</imu>
	</sensor>
	<sensor name="air_pressure_sensor" type="air_pressure">
		<always_on>1</always_on>
		<update_rate>50</update_rate>
		<air_pressure>
			<pressure>
				<noise type="gaussian">
					<mean>0</mean>
					<stddev>0.01</stddev>
				</noise>
			</pressure>
		</air_pressure>
	</sensor>
	<sensor name="magnetometer_sensor" type="magnetometer">
		<always_on>1</always_on>
		<update_rate>100</update_rate>
		<magnetometer>
			<!-- TODO: update to fix units and coordinate system when we move past Harmonic -->
			<!-- See https://github.com/gazebosim/gz-sim/pull/2460 -->
			<!-- 3mgauss RMS: NOTE: noise is in tesla but sensor reports data in gauss -->
			<!-- Noise modeled after IIS2MDC -->
			<x>
				<noise type="gaussian">
				<stddev>0.0001</stddev>
				</noise>
			</x>
			<y>
				<noise type="gaussian">
				<stddev>0.0001</stddev>
				</noise>
			</y>
			<z>
				<noise type="gaussian">
				<stddev>0.0001</stddev>
				</noise>
			</z>
		</magnetometer>
	</sensor>
	<sensor name="navsat_sensor" type="navsat">
		<always_on>1</always_on>
		<update_rate>30</update_rate>
	</sensor>
	  </link>
	  <link name="jet_ski/EngineProp">
	    <pose relative_to="jet_ski/EnginePropJoint">0 0 0 0 0 0</pose>
	    <inertial>
	      <mass>.5</mass>
	      <inertia>
		  <ixx>0.8545</ixx>
		  <ixy>0</ixy>
		  <ixz>0</ixz>
		  <iyy>0.8545</iyy>
		  <iyz>0</iyz>
		  <izz>0.144</izz>
	      </inertia>
	    </inertial>
	    <gravity>true</gravity>
	    <velocity_decay/>
	    <visual name="jet_ski/EnginePropVisual">
	      <pose relative_to="jet_ski/EnginePropJoint">0 0 0 1.57 0 0</pose>
	      <geometry>
		<cylinder>
		   <radius>0.1</radius>
		   <length>0.05</length>
		</cylinder>
	      </geometry>
		<material>
		<ambient>0.2 0.2 0.2 1</ambient>
		<diffuse>0.6 0.6 0.6 1</diffuse>
	      </material>
	    </visual>
	    <collision name="jet_ski/EnginePropVisualCollision">
	      <pose relative_to="jet_ski/EnginePropJoint">0 0 0 0 0 0</pose>
	      <geometry>
		<cylinder>
		  <length>0.05</length>
		  <radius>0.1</radius>
		</cylinder>
	      </geometry>
	      <surface>
		<friction>
		  <ode>
			<mu>1.0</mu>
			<mu2>1.0</mu2>
			<fdir1>1 0 0</fdir1>
		  </ode>
		</friction>
	      </surface>
	    </collision>
	  </link>
	  <link name="jet_ski/EngineSteering">
	    <pose relative_to="servo_0">0 0 0 0 0 0</pose>
	    <inertial>
	      <mass>0.05</mass>
	      <inertia>
		<ixx>0.000018</ixx>
		<iyy>0.000018</iyy>
		<izz>0.000018</izz>
	      </inertia>
	    </inertial>
	  </link>
	  
	  <joint name="servo_0" type="revolute">
	    <parent>base_link</parent>
	    <child>jet_ski/EngineSteering</child>
	    <pose relative_to="base_link">0 1.3 -0.5 0 0 0</pose>
	    <axis>
	      <xyz>0 0 1</xyz>
	      <limit>
		<lower>-0.2</lower>
		<upper>0.2</upper>
		<velocity>1.0</velocity>
		<effort>25</effort>
	      </limit>
	      <use_parent_model_frame>1</use_parent_model_frame>
	    </axis>
	  </joint>
	  <joint name="jet_ski/EnginePropJoint" type="revolute">
	    <parent>jet_ski/EngineSteering</parent>
	    <child>jet_ski/EngineProp</child>
	    <pose relative_to="servo_0">0 -0.05 0 0 0 0</pose>
	    <axis>
	      <xyz>0 1 0</xyz>
	      <limit>
		<lower>-1.79769e+308</lower>
		<upper>1.79769e+308</upper>
		<velocity>50.0</velocity>
	      </limit>
	      <dynamics>
		<spring_reference>0</spring_reference>
		<spring_stiffness>0</spring_stiffness>
	      </dynamics>
	      <use_parent_model_frame>1</use_parent_model_frame>
	    </axis>
	  </joint>
	  

	  
	  <plugin filename="gz-sim-joint-controller-system" name="gz::sim::systems::JointController">
		<joint_name>jet_ski/EnginePropJoint</joint_name>
	        <sub_topic>command/motor_speed</sub_topic>
	        <use_actuator_msg>true</use_actuator_msg>
	        <actuator_number>0</actuator_number>
		<p_gain>10.0</p_gain>
	  </plugin>

		<plugin
		filename="gz-sim-joint-state-publisher-system"
		name="gz::sim::systems::JointStatePublisher">
			<joint_name>jet_ski/EnginePropJoint</joint_name>
			<joint_name>servo_0</joint_name>
	</plugin>
	<plugin
		filename="gz-sim-joint-position-controller-system" name="gz::sim::systems::JointPositionController">
		<joint_name>servo_0</joint_name>
		<sub_topic>servo_0</sub_topic>
		<p_gain>10</p_gain>
		<i_gain>0</i_gain>
		<d_gain>0</d_gain>
	</plugin>
	



	</model>
      </sdf>
